[2025-01-27T04:22:26.196+0000] {taskinstance.py:1165} INFO - Dependencies all met for <TaskInstance: user_processing.process_users manual__2025-01-27T04:22:21.652559+00:00 [queued]>
[2025-01-27T04:22:26.207+0000] {taskinstance.py:1165} INFO - Dependencies all met for <TaskInstance: user_processing.process_users manual__2025-01-27T04:22:21.652559+00:00 [queued]>
[2025-01-27T04:22:26.208+0000] {taskinstance.py:1362} INFO - 
--------------------------------------------------------------------------------
[2025-01-27T04:22:26.209+0000] {taskinstance.py:1363} INFO - Starting attempt 1 of 1
[2025-01-27T04:22:26.209+0000] {taskinstance.py:1364} INFO - 
--------------------------------------------------------------------------------
[2025-01-27T04:22:26.225+0000] {taskinstance.py:1383} INFO - Executing <Task(PythonOperator): process_users> on 2025-01-27 04:22:21.652559+00:00
[2025-01-27T04:22:26.231+0000] {standard_task_runner.py:55} INFO - Started process 6879 to run task
[2025-01-27T04:22:26.234+0000] {standard_task_runner.py:82} INFO - Running: ['***', 'tasks', 'run', 'user_processing', 'process_users', 'manual__2025-01-27T04:22:21.652559+00:00', '--job-id', '21', '--raw', '--subdir', 'DAGS_FOLDER/user_processing.py', '--cfg-path', '/tmp/tmpezhdo03o']
[2025-01-27T04:22:26.236+0000] {standard_task_runner.py:83} INFO - Job 21: Subtask process_users
[2025-01-27T04:22:26.303+0000] {task_command.py:376} INFO - Running <TaskInstance: user_processing.process_users manual__2025-01-27T04:22:21.652559+00:00 [running]> on host e298d0337d0c
[2025-01-27T04:22:26.382+0000] {taskinstance.py:1592} INFO - Exporting the following env vars:
AIRFLOW_CTX_DAG_OWNER=***
AIRFLOW_CTX_DAG_ID=user_processing
AIRFLOW_CTX_TASK_ID=process_users
AIRFLOW_CTX_EXECUTION_DATE=2025-01-27T04:22:21.652559+00:00
AIRFLOW_CTX_TRY_NUMBER=1
AIRFLOW_CTX_DAG_RUN_ID=manual__2025-01-27T04:22:21.652559+00:00
[2025-01-27T04:22:26.394+0000] {taskinstance.py:1851} ERROR - Task failed with exception
Traceback (most recent call last):
  File "/home/airflow/.local/lib/python3.7/site-packages/airflow/operators/python.py", line 175, in execute
    return_value = self.execute_callable()
  File "/home/airflow/.local/lib/python3.7/site-packages/airflow/operators/python.py", line 193, in execute_callable
    return self.python_callable(*self.op_args, **self.op_kwargs)
  File "/opt/airflow/dags/user_processing.py", line 12, in _process_user
    user=user['results'][0]
UnboundLocalError: local variable 'user' referenced before assignment
[2025-01-27T04:22:26.407+0000] {taskinstance.py:1406} INFO - Marking task as FAILED. dag_id=user_processing, task_id=process_users, execution_date=20250127T042221, start_date=20250127T042226, end_date=20250127T042226
[2025-01-27T04:22:26.419+0000] {standard_task_runner.py:105} ERROR - Failed to execute job 21 for task process_users (local variable 'user' referenced before assignment; 6879)
[2025-01-27T04:22:26.446+0000] {local_task_job.py:164} INFO - Task exited with return code 1
[2025-01-27T04:22:26.467+0000] {local_task_job.py:273} INFO - 0 downstream tasks scheduled from follow-on schedule check
